Workbook

Sheet 28-08
A1: المتأخر المدين حتى 28-08-2026
A3: المتأخر المدين | B3: الشركة | C3: علامات التصنيف | D3: شروط السداد للعميل | E3: مندوب المبيعات | F3: بتاريخ | G3: 1-30 | H3: 31-60 | I3: 61-90 | J3: 91-120 | K3: أقدم | L3: الإجمالي
F4: =SUBTOTAL(9,F5:F270) -> 77152.6 | G4: =SUBTOTAL(9,G5:G270) -> 39366 | H4: =SUBTOTAL(9,H5:H270) -> 12150 | I4: =SUBTOTAL(9,I5:I270) -> 5435 | J4: =SUBTOTAL(9,J5:J270) -> 0 | K4: =SUBTOTAL(9,K5:K270) -> 4004255.1 | L4: =SUBTOTAL(9,L5:L270) -> 4138358.7
A5: خالد حسين (عميل - مورد) | B5: 0 | C5: عميل - مورد | D5: 0 | E5: Haddil Haron | F5: 0 | G5: 4342873.5 | H5: 3877405.2 | I5: 0 | J5: 886378.79 | K5: 0 | L5: 9106657.5
A6: تسيباس اوول فوود | B6: MAS | C6: عملاء اجل | D6: 30 يوماً | E6: Haddil Haron | F6: 2272096 | G6: 1364858.3 | H6: 246187.5 | I6: 0 | J6: 190187.66 | K6: 0 | L6: 4073329.5
A7: سدرة - للحلويات | B7: MAS | C7: عملاء اجل | D7: 15 of month | E7: Haddil Haron | F7: 1227970 | G7: 793521.9 | H7: 0 | I7: 0 | J7: 927344.29 | K7: 0 | L7: 2948836.2
A8: فوالا | B8: MAS | C8: عملاء اجل | D8: 60 يوم | E8: Haddil Haron | F8: 1824932.4 | G8: 485100.6 | H8: 17913 | I8: 0 | J8: 582364.27 | K8: 0 | L8: 2910310.3
A9: زانوبيا | B9: MAS | C9: عملاء اجل | D9: 15 of month | E9: Haddil Haron | F9: 979180 | G9: 352005 | H9: 832327.44 | I9: 210000 | J9: 0 | K9: 0 | L9: 2373512.4
A10: مصنع بريد فاست | B10: MAS | C10: عملاء اجل | D10: 30 يوماً | E10: Haddil Haron | F10: 2181891 | G10: 0 | H10: 0 | I10: 0 | J10: 46254.23 | K10: 0 | L10: 2228145.2
A11: ايتوال | B11: MAS | C11: عملاء اجل | D11: 15 of month | E11: Haddil Haron | F11: 2131901.2 | G11: 0 | H11: 0 | I11: 0 | J11: 0 | K11: 0 | L11: 2131901.2
A12: نولا | B12: MAS | C12: عملاء اجل | D12: 15 of month | E12: Haddil Haron | F12: 1293044 | G12: 769850.28 | H12: 0 | I12: 0 | J12: 0 | K12: 0 | L12: 2062894.3
A13: شركة الدهان لادارة المشروعات السياحية | B13: MAS | C13: عملاء اجل | D13: 10 يوماً | E13: Haddil Haron | F13: 0 | G13: 2004570.8 | H13: 0 | I13: 22223.47 | J13: 0 | K13: 0 | L13: 2026794.2
A14: سموزى برادايس | B14: MAS | C14: عملاء اجل | D14: 15 يوماً | E14: Haddil Haron | F14: 1039115.6 | G14: 545887.41 | H14: 0 | I14: 0 | J14: 154204.11 | K14: 0 | L14: 1739207.1
A15: توينكى | B15: MAS | C15: متجمد | D15: 0 | E15: Naden Amgad | F15: 0 | G15: 0 | H15: 0 | I15: 0 | J15: 0 | K15: 1478937 | L15: 1478937
A16: شركة وهمى | B16: MAS | C16: عملاء اجل | D16: 30 يوماً | E16: Haddil Haron | F16: 0 | G16: 39366 | H16: 12000 | I16: 0 | J16: 0 | K16: 1369387.2 | L16: 1420753.2
A17: ناديةمحمد عبد الغنى ابو طالب | B17: 0 | C17: عملاء كاش | D17: الدفع الفوري | E17: AbdElrhaman Farrag | F17: 0 | G17: 1409941.8 | I17: 0 | J17: 0 | K17: 0 | L17: 1409941.8
A18: جيت للتجارة والتوزيع JET- الاقاليم | B18: MAS | C18: عميل - مورد | D18: الدفع الفوري | E18: Amgad Ahmed | F18: 0 | G18: 1076699.3 | H18: 0 | I18: 0 | J18: 0 | K18: 0 | L18: 1076699.3
A19: شركة الرواد لتوريد المواد الغذائية | B19: 0 | C19: عميل - مورد | D19: 0 | E19: Amgad Ahmed | F19: 0 | G19: 459182.38 | I19: 304042.3 | J19: 275156.6 | K19: 0 | L19: 1038381.3
A20: ماتانا للمنتجات الغذائية | B20: MAS | C20: عملاء اجل | D20: 30 يوماً | E20: Haddil Haron | F20: 793900 | G20: 45351 | H20: 117104.29 | I20: 50018.22 | J20: 0 | K20: 0 | L20: 1006373.5
A21: طبالي | B21: MAS | C21: عملاء اجل | D21: 15 يوماً | E21: Haddil Haron | F21: 108057.25 | G21: 134100 | H21: 320187.3 | I21: 0 | J21: 416516.24 | K21: 0 | L21: 978860.79
A22: مصنع الرياده عطيه أمام | B22: Horeca Smart | C22: عملاء اجل | D22: 10 أيام بعد نهاية الشهر التالي | E22: Donia Khaled | F22: 587244.72 | G22: 361949.41 | I22: 0 | J22: 0 | K22: 0 | L22: 949193.02
A23: بابا جونز(فانتدج ايجيبت) | B23: MAS | C23: عملاء اجل | D23: 30 يوماً | E23: Haddil Haron | F23: 362102 | G23: 25244 | H23: 557422.66 | I23: 0 | J23: 200.78 | K23: 0 | L23: 944969.44
A24: حلواني بالمي | B24: Horeca Smart | C24: عملاء اجل | D24: 15 of month | E24: Mona Mohamed | F24: 701539.69 | G24: 232017.5 | H24: 105 | I24: 88.6 | J24: 0 | K24: 0 | L24: 933750.79
A25: مطعم مايند دن | B25: MAS | C25: عملاء اجل | D25: 30 يوماً | E25: Haddil Haron | F25: 864444.8 | G25: 61140.79 | H25: 0 | I25: 2.15 | J25: 19.95 | K25: 0 | L25: 925607.69
A26: Horeca Hub | B26: Horeca Smart | C26: عملاء اجل | D26: 15 يوماً | E26: Mona Mohamed | F26: 512598.6 | G26: 346479.17 | H26: 13999.96 | I26: 8598.52 | J26: 644.67 | K26: 0 | L26: 882320.92
A27: عم شلتت للمخبوزات | B27: MAS | C27: عملاء اجل | D27: 15 يوماً | E27: Haddil Haron | F27: 181421.5 | G27: 526133.5 | H27: 140516.95 | I27: 0 | J27: 0 | K27: 0 | L27: 848071.95
A28: بلبن | B28: MAS | C28: عملاء اجل | D28: 30 يوماً | E28: Haddil Haron | F28: 0 | G28: 183060 | H28: 1950 | I28: 0 | J28: 652132 | K28: 0 | L28: 837142
A29: Chicken Balalm | B29: MAS | C29: عملاء اجل | D29: 15 يوماً | E29: Haddil Haron | F29: 101600 | G29: 292710 | H29: 196237.96 | I29: 0 | J29: 227050 | K29: 0 | L29: 817597.96
A30: ميسو | B30: MAS | C30: عملاء اجل | D30: 0 | E30: Haddil Haron | F30: 0 | G30: 404942.6 | H30: 279956.75 | I30: 0 | J30: 0 | K30: 0 | L30: 684899.35
A31: Abela | B31: MAS | C31: عملاء اجل | D31: 30 يوماً | E31: Haddil Haron | F31: 210311.2 | G31: 267680.98 | H31: 164538 | I31: 0 | J31: 0 | K31: 0 | L31: 642530.18
A32: Simonds Bakery | B32: MAS | C32: عملاء اجل | D32: 15 يوماً | E32: Haddil Haron | F32: 205901.1 | G32: 433476 | H32: 0 | I32: 0 | J32: 0 | K32: 0 | L32: 639377.1
A33: حلواني بيست سويت | B33: MAS | C33: عملاء اجل | D33: 15 of month | E33: Haddil Haron | F33: 507299.44 | G33: 66995.85 | H33: 7855.5 | I33: 0 | J33: 0 | K33: 0 | L33: 582150.79
A34: مونجينى | B34: MAS | C34: عملاء اجل | D34: 15 of month | E34: Haddil Haron | F34: 0 | G34: 0 | H34: 0 | I34: 317400 | J34: 221580.74 | K34: 0 | L34: 538980.74
A35: كبدة الفلاح - الالف مصنع | B35: MAS | C35: متجمد | D35: 0 | E35: Donia Khaled | F35: 0 | G35: 0 | H35: 0 | I35: 0 | J35: 0 | K35: 515589.97 | L35: 515589.97
A36: السويفى ( عميل ومورد ) | B36: MAS | C36: عميل - مورد | D36: الدفع الفوري | E36: Haddil Haron | F36: 0 | G36: 0 | H36: 487719 | K36: 0 | L36: 487719
A37: لينورا للحلويات والمخبوزات | B37: MAS | C37: عملاء اجل | D37: 15 of month | E37: Haddil Haron | F37: 137786 | G37: 206009.15 | H37: 103415.65 | I37: 0 | J37: 0 | K37: 0 | L37: 447210.8
A38: شركة جيت | B38: MAS | C38: عملاء كاش | D38: الدفع الفوري | E38: Haddil Haron | F38: 0 | G38: 422992.8 | H38: 0 | I38: 0 | J38: 0 | K38: 0 | L38: 422992.8
A39: بهيج | B39: MAS | C39: عملاء اجل | D39: 30 يوماً | E39: Haddil Haron | F39: 0 | G39: 0 | H39: 0 | I39: 0 | J39: 408176.14 | K39: 0 | L39: 408176.14
A40: احمد يوسف ( عميل و مورد ) | B40: MAS | C40: عميل - مورد | D40: 5 Days | E40: Haddil Haron | F40: 0 | G40: 0 | H40: 0 | I40: 0 | J40: 363946.82 | K40: 0 | L40: 363946.82
A41: Burger Republic | B41: Horeca Smart | C41: عملاء اجل | D41: 15 of month | E41: Mona Mohamed | F41: 76000 | G41: 0 | H41: 286488.73 | I41: 0 | J41: 0 | K41: 0 | L41: 362488.73
...

Sheet 02-09
A1: المتأخر المدين حتى 02-09-2026
A3: المتأخر المدين | B3: الشركة | C3: علامات التصنيف | D3: شروط السداد للعميل | E3: مندوب المبيعات | F3: بتاريخ | G3: 1-30 | H3: 31-60 | I3: 61-90 | J3: 91-120 | K3: أقدم | L3: الإجمالي
F4: =SUBTOTAL(9,F5:F257) -> 23314907 | G4: =SUBTOTAL(9,G5:G257) -> 18962081 | H4: =SUBTOTAL(9,H5:H257) -> 7619991.9 | I4: =SUBTOTAL(9,I5:I257) -> -854074.65 | J4: =SUBTOTAL(9,J5:J257) -> 8834090.9 | K4: =SUBTOTAL(9,K5:K257) -> 3994898.9 | L4: =SUBTOTAL(9,L5:L257) -> 61871896
A5: خالد حسين (عميل - مورد) | B5: 0 | C5: عميل - مورد | D5: 0 | E5: Haddil Haron | F5: 0 | G5: 5288126 | H5: 3877405.2 | I5: 0 | J5: 886378.79 | K5: 0 | L5: 10051910
A6: تسيباس اوول فوود | B6: MAS | C6: عملاء اجل | D6: 30 يوماً | E6: Haddil Haron | F6: 2300096 | G6: 680123.89 | H6: 246187.5 | I6: 0 | J6: 190187.66 | K6: 0 | L6: 3416595.1
A7: زانوبيا | B7: MAS | C7: عملاء اجل | D7: 15 of month | E7: Haddil Haron | F7: 1225775 | G7: 352005 | H7: 832327.44 | I7: 210000 | J7: 0 | K7: 0 | L7: 2620107.4
A8: سموزى برادايس | B8: MAS | C8: عملاء اجل | D8: 15 يوماً | E8: Haddil Haron | F8: 1752877.4 | G8: 545887.41 | H8: 0 | I8: 0 | J8: 154204.11 | K8: 0 | L8: 2452968.9
A9: سدرة - للحلويات | B9: MAS | C9: عملاء اجل | D9: 15 of month | E9: Haddil Haron | F9: 1286784.6 | G9: 218751.05 | H9: 0 | I9: 0 | J9: 927344.29 | K9: 0 | L9: 2432880
A10: فوالا | B10: MAS | C10: عملاء اجل | D10: 60 يوم | E10: Haddil Haron | F10: 1324932.4 | G10: 485100.6 | H10: 17913 | I10: 0 | J10: 582364.27 | K10: 0 | L10: 2410310.3
A11: مصنع بريد فاست | B11: MAS | C11: عملاء اجل | D11: 30 يوماً | E11: Haddil Haron | F11: 2181891 | G11: 0 | H11: 0 | I11: 0 | J11: 46254.23 | K11: 0 | L11: 2228145.2
A12: ايتوال | B12: MAS | C12: عملاء اجل | D12: 15 of month | E12: Haddil Haron | F12: 2131901.2 | G12: 0 | H12: 0 | I12: 0 | J12: 0 | K12: 0 | L12: 2131901.2
A13: نولا | B13: MAS | C13: عملاء اجل | D13: 15 of month | E13: Haddil Haron | F13: 1293044 | G13: 769850.28 | H13: 0 | I13: 0 | J13: 0 | K13: 0 | L13: 2062894.3
A14: شركة الدهان لادارة المشروعات السياحية | B14: MAS | C14: عملاء اجل | D14: 10 يوماً | E14: Haddil Haron | F14: 0 | G14: 2004570.8 | H14: 0 | I14: 22223.47 | J14: 0 | K14: 0 | L14: 2026794.2
A15: توينكى | B15: MAS | C15: متجمد | D15: 0 | E15: Naden Amgad | F15: 0 | G15: 0 | H15: 0 | I15: 0 | K15: 1478937 | L15: 1478937
A16: شركة وهمى | B16: MAS | C16: عملاء اجل | D16: 30 يوماً | E16: Haddil Haron | F16: 0 | G16: 39366 | H16: 12000 | I16: 0 | K16: 1369387.2 | L16: 1420753.2
A17: جيت للتجارة والتوزيع JET | B17: MAS | F17: 0 | G17: 1293071.2 | H17: 0 | I17: 0 | J17: 0 | K17: 0 | L17: 1293071.2
A18: ماتانا للمنتجات الغذائية | B18: MAS | C18: عملاء اجل | D18: 30 يوماً | E18: Haddil Haron | F18: 793900 | G18: 45351 | H18: 117104.29 | I18: 50018.22 | J18: 0 | K18: 0 | L18: 1006373.5
A19: مطعم مايند دن | B19: MAS | C19: عملاء اجل | D19: 30 يوماً | E19: Haddil Haron | F19: 943754.72 | G19: 61140.79 | H19: 0 | I19: 2.15 | J19: 19.95 | K19: 0 | L19: 1004917.6
A20: طبالي | B20: MAS | C20: عملاء اجل | D20: 15 يوماً | E20: Haddil Haron | F20: 108057.25 | G20: 134100 | H20: 320187.3 | I20: 0 | J20: 416516.24 | K20: 0 | L20: 978860.79
A21: مصنع الرياده عطيه أمام | B21: Horeca Smart | C21: عملاء اجل | D21: 10 أيام بعد نهاية الشهر التالي | E21: Donia Khaled | F21: 587244.72 | G21: 374800.61 | H21: -1.11 | I21: 0 | J21: 0 | K21: 0 | L21: 962044.22
A22: بابا جونز(فانتدج ايجيبت) | B22: MAS | C22: عملاء اجل | D22: 30 يوماً | E22: Haddil Haron | F22: 362102 | G22: 25244 | H22: 557422.66 | I22: 0 | J22: 200.78 | K22: 0 | L22: 944969.44
A23: عم شلتت للمخبوزات | B23: MAS | C23: عملاء اجل | D23: 15 يوماً | E23: Haddil Haron | F23: 367636.5 | G23: 526133.5 | H23: 40516.95 | I23: 0 | J23: 0 | K23: 0 | L23: 934286.95
A24: حلواني بالمي | B24: Horeca Smart | C24: عملاء اجل | D24: 15 of month | E24: Mona Mohamed | F24: 701539.69 | G24: 231730 | H24: 392.5 | I24: 88.6 | J24: 0 | K24: 0 | L24: 933750.79
A25: Horeca Hub | B25: Horeca Smart | C25: عملاء اجل | D25: 15 يوماً | E25: Mona Mohamed | F25: 802188.6 | G25: 79487.65 | H25: 0 | I25: 0 | J25: 644.67 | K25: 0 | L25: 882320.92
A26: شركة الرواد لتوريد المواد الغذائية | B26: 0 | C26: عميل - مورد | D26: 0 | E26: Amgad Ahmed | F26: 58925 | G26: 379657.38 | H26: -100000 | I26: 256042.3 | J26: 275156.6 | K26: 0 | L26: 869781.28
A27: بلبن | B27: MAS | C27: عملاء اجل | D27: 30 يوماً | E27: Haddil Haron | F27: 0 | G27: 183060 | H27: 1950 | I27: 0 | J27: 652132 | K27: 0 | L27: 837142
A28: Chicken Balalm | B28: MAS | C28: عملاء اجل | D28: 15 يوماً | E28: Haddil Haron | F28: 218600 | G28: 192710 | H28: 116237.96 | I28: 0 | J28: 227050 | K28: 0 | L28: 754597.96
A29: ميسو | B29: MAS | C29: عملاء اجل | D29: 0 | E29: Haddil Haron | F29: 0 | G29: 404942.6 | H29: 279956.75 | I29: 0 | J29: 0 | K29: 0 | L29: 684899.35
A30: Simonds Bakery | B30: MAS | C30: عملاء اجل | D30: 15 يوماً | E30: Haddil Haron | F30: 205901.1 | G30: 433476 | H30: 0 | I30: 0 | J30: 0 | K30: 0 | L30: 639377.1
A31: ناديةمحمد عبد الغنى ابو طالب | B31: 0 | C31: عملاء كاش | D31: الدفع الفوري | E31: AbdElrhaman Farrag | F31: 0 | G31: 774942.4 | H31: -160000.6 | I31: 0 | J31: 0 | K31: 0 | L31: 614941.8
A32: لينورا للحلويات والمخبوزات | B32: MAS | C32: عملاء اجل | D32: 15 of month | E32: Haddil Haron | F32: 283331.76 | G32: 206009.15 | H32: 103415.65 | I32: 0 | J32: 0 | K32: 0 | L32: 592756.56
A33: حلواني بيست سويت | B33: MAS | C33: عملاء اجل | D33: 15 of month | E33: Haddil Haron | F33: 507299.44 | G33: 66995.85 | H33: 7855.5 | I33: 0 | J33: 0 | K33: 0 | L33: 582150.79
A34: مونجينى | B34: MAS | C34: عملاء اجل | D34: 15 of month | E34: Haddil Haron | F34: 0 | G34: 0 | H34: 0 | I34: 317400 | J34: 221580.74 | K34: 0 | L34: 538980.74
A35: كبدة الفلاح - الالف مصنع | B35: MAS | C35: متجمد | D35: 0 | E35: Donia Khaled | F35: 0 | G35: 0 | H35: 0 | I35: 0 | K35: 515589.97 | L35: 515589.97
A36: Burger Republic | B36: Horeca Smart | C36: عملاء اجل | D36: 15 of month | E36: Mona Mohamed | F36: 228000 | G36: -256211.48 | H36: 286488.73 | I36: 0 | J36: 256211.48 | K36: 0 | L36: 514488.73
A37: السويفى ( عميل ومورد ) | B37: MAS | C37: عميل - مورد | D37: الدفع الفوري | E37: Haddil Haron | F37: 0 | G37: 0 | H37: 487719 | I37: -1103289 | J37: 1103289 | K37: 0 | L37: 487719
A38: شركة جيت | B38: MAS | C38: عملاء كاش | D38: الدفع الفوري | E38: Haddil Haron | F38: 0 | G38: 422992.8 | H38: 0 | I38: 0 | J38: 0 | K38: 0 | L38: 422992.8
A39: بهيج | B39: MAS | C39: عملاء اجل | D39: 30 يوماً | E39: Haddil Haron | F39: 0 | G39: 0 | H39: 0 | I39: 0 | J39: 408176.14 | K39: 0 | L39: 408176.14
A40: شركة تارجت للمواد الغذائية | B40: MAS | C40: عملاء اجل | D40: 15 of month | E40: Haddil Haron | F40: 322827.49 | G40: 47735.61 | H40: 0 | I40: 0 | J40: 0 | K40: 0 | L40: 370563.1
A41: Abela | B41: MAS | C41: عملاء اجل | D41: 30 يوماً | E41: Haddil Haron | F41: 361686.16 | G41: 4388.07 | H41: 0 | I41: 0 | J41: 0 | K41: 0 | L41: 366074.23
...

Sheet 09-09
A1: المتأخر المدين حتى 09-09-2026
A3: المتأخر المدين | B3: الشركة | C3: علامات التصنيف | D3: شروط السداد للعميل | E3: مندوب المبيعات | F3: بتاريخ | G3: 1-30 | H3: 31-60 | I3: 61-90 | J3: 91-120 | K3: أقدم | L3: الإجمالي
F4: =SUBTOTAL(9,F5:F233) -> 21663548 | G4: =SUBTOTAL(9,G5:G233) -> 17369295 | H4: =SUBTOTAL(9,H5:H233) -> 11220716 | I4: =SUBTOTAL(9,I5:I233) -> 817366.58 | J4: =SUBTOTAL(9,J5:J233) -> 11383000 | K4: =SUBTOTAL(9,K5:K233) -> 0 | L4: =SUBTOTAL(9,L5:L233) -> 62453925
A5: خالد حسين (عميل - مورد) | B5: 0 | C5: عميل - مورد | D5: 0 | E5: Haddil Haron | F5: 0 | G5: 2240470 | H5: 6225061.2 | I5: 0 | J5: 596748.59 | K5: 0 | L5: 9062279.8
A6: تسيباس اوول فوود | B6: MAS | C6: عملاء اجل | D6: 30 يوماً | E6: Haddil Haron | F6: 579309.88 | G6: 2437930 | H6: 37487 | I6: 213200.5 | J6: 190187.66 | K6: 0 | L6: 3458115.1
A7: سموزى برادايس | B7: MAS | C7: عملاء اجل | D7: 15 يوماً | E7: Haddil Haron | F7: 917118.37 | G7: 1585003 | H7: 0 | I7: 0 | J7: 154204.11 | K7: 0 | L7: 2656325.5
A8: زانوبيا | B8: MAS | C8: عملاء اجل | D8: 15 of month | E8: Haddil Haron | F8: 1248260 | G8: 352005 | H8: 832327.44 | I8: 210000 | J8: 0 | K8: 0 | L8: 2642592.4
A9: ايتوال | B9: MAS | C9: عملاء اجل | D9: 15 of month | E9: Haddil Haron | F9: 1544636.8 | G9: 1083300 | H9: 0 | I9: 0 | J9: 0 | K9: 0 | L9: 2627936.7
A10: سدرة - للحلويات | B10: MAS | C10: عملاء اجل | D10: 15 of month | E10: Haddil Haron | F10: 1457394.2 | G10: 218751.05 | H10: 0 | I10: 0 | J10: 927344.29 | K10: 0 | L10: 2603489.5
A11: فوالا | B11: MAS | C11: عملاء اجل | D11: 60 يوم | E11: Haddil Haron | F11: 1948050.3 | G11: -434872.85 | H11: 503013.6 | I11: 0 | J11: 582364.27 | K11: 0 | L11: 2598555.3
A12: مصنع بريد فاست | B12: MAS | C12: عملاء اجل | D12: 30 يوماً | E12: Haddil Haron | F12: 422280 | G12: 1759611 | H12: 0 | I12: 0 | J12: 46254.23 | K12: 0 | L12: 2228145.2
A13: نولا | B13: MAS | C13: عملاء اجل | D13: 15 of month | E13: Haddil Haron | F13: 1477612 | G13: 148161.48 | H13: 0 | I13: 0 | J13: 0 | K13: 0 | L13: 1625773.5
A14: توينكى | B14: MAS | C14: متجمد | D14: 0 | E14: Naden Amgad | F14: 0 | G14: 0 | H14: 0 | I14: 0 | J14: 1478937 | K14: 0 | L14: 1478937
A15: شركة وهمى | B15: MAS | C15: عملاء اجل | D15: 30 يوماً | E15: Haddil Haron | F15: 0 | G15: 0 | H15: 51366 | I15: 0 | J15: 1369387.2 | K15: 0 | L15: 1420753.2
A16: ماتانا للمنتجات الغذائية | B16: MAS | C16: عملاء اجل | D16: 30 يوماً | E16: Haddil Haron | F16: 782958.75 | G16: 469284 | H16: 91160 | I16: 75962.51 | J16: 0 | K16: 0 | L16: 1419365.3
A17: Abela | B17: MAS | C17: عملاء اجل | D17: 30 يوماً | E17: Haddil Haron | F17: 1408066.2 | G17: 4388.07 | H17: 0 | I17: 0 | J17: 0 | K17: 0 | L17: 1412454.3
A18: جيت للتجارة والتوزيع JET | B18: #N/A | C18: #N/A | D18: 0 | E18: #N/A | F18: 0 | G18: 1223686.2 | H18: 175454.5 | I18: 0 | J18: 0 | K18: 0 | L18: 1399140.7
A19: بابا جونز(فانتدج ايجيبت) | B19: MAS | C19: عملاء اجل | D19: 30 يوماً | E19: Haddil Haron | F19: 800232.92 | G19: 29350 | H19: 557422.66 | I19: 0 | J19: 200.78 | K19: 0 | L19: 1387206.4
A20: Chicken Balalm | B20: MAS | C20: عملاء اجل | D20: 15 يوماً | E20: Haddil Haron | F20: 582800 | G20: 132110 | H20: 278437.96 | I20: 0 | J20: 227050 | K20: 0 | L20: 1220398
A21: مطعم مايند دن | B21: MAS | C21: عملاء اجل | D21: 30 يوماً | E21: Haddil Haron | F21: 715076.37 | G21: 381241.94 | H21: 60970.1 | I21: 2.15 | J21: 19.95 | K21: 0 | L21: 1157310.5
A22: طبالي | B22: MAS | C22: عملاء اجل | D22: 15 يوماً | E22: Haddil Haron | F22: 108057.25 | G22: 134100 | H22: 320187.3 | I22: 0 | J22: 416516.24 | K22: 0 | L22: 978860.79
A23: عم شلتت للمخبوزات | B23: MAS | C23: عملاء اجل | D23: 15 يوماً | E23: Haddil Haron | F23: 384820 | G23: 455594.5 | H23: 54977.45 | I23: 0 | J23: 0 | K23: 0 | L23: 895391.95
A24: حلواني بيست سويت | B24: MAS | C24: عملاء اجل | D24: 15 of month | E24: Haddil Haron | F24: 767382.2 | G24: 66995.85 | H24: 7855.5 | I24: 0 | J24: 0 | K24: 0 | L24: 842233.55
A25: شركة جيت | B25: MAS | C25: عملاء كاش | D25: الدفع الفوري | E25: Haddil Haron | F25: 0 | G25: 837760.74 | H25: 0 | I25: 0 | J25: 0 | K25: 0 | L25: 837760.74
A26: بلبن | B26: MAS | C26: عملاء اجل | D26: 30 يوماً | E26: Haddil Haron | F26: 0 | G26: 6125 | H26: 178885 | I26: 0 | J26: 652132 | K26: 0 | L26: 837142
A27: ميسو | B27: MAS | C27: عملاء اجل | D27: 0 | E27: Haddil Haron | F27: 148155 | G27: 297138.75 | H27: 387760.6 | I27: 0 | J27: 0 | K27: 0 | L27: 833054.35
A28: شركة الرواد لتوريد المواد الغذائية | B28: 0 | C28: عميل - مورد | D28: 0 | E28: Amgad Ahmed | F28: 50890 | G28: 389565 | H28: 160492.38 | I28: 175495.51 | J28: 45691.05 | K28: 0 | L28: 822133.94
A29: حلواني بالمي | B29: Horeca Smart | C29: عملاء اجل | D29: 15 of month | E29: Mona Mohamed | F29: 701539.69 | G29: 0 | H29: 392.5 | I29: 0 | J29: 88.6 | K29: 0 | L29: 702020.79
A30: Simonds Bakery | B30: MAS | C30: عملاء اجل | D30: 15 يوماً | E30: Haddil Haron | F30: 205901.1 | G30: 433476 | H30: 0 | I30: 0 | J30: 0 | K30: 0 | L30: 639377.1
A31: Burger Republic | B31: Horeca Smart | C31: عملاء اجل | D31: 15 of month | E31: Mona Mohamed | F31: 311680 | G31: 0 | H31: 30277.25 | I31: 0 | J31: 256211.48 | K31: 0 | L31: 598168.73
A32: مونجينى | B32: MAS | C32: عملاء اجل | D32: 15 of month | E32: Haddil Haron | F32: 0 | G32: 0 | H32: 0 | I32: 0 | J32: 538980.74 | K32: 0 | L32: 538980.74
A33: شركة تارجت للمواد الغذائية | B33: MAS | C33: عملاء اجل | D33: 15 of month | E33: Haddil Haron | F33: 480863.53 | G33: 47735.61 | H33: 0 | I33: 0 | J33: 0 | K33: 0 | L33: 528599.14
A34: كبدة الفلاح - الالف مصنع | B34: MAS | C34: متجمد | D34: 0 | E34: Donia Khaled | F34: 0 | G34: 0 | H34: 0 | I34: 0 | J34: 515589.97 | K34: 0 | L34: 515589.97
A35: ناديةمحمد عبد الغنى ابو طالب | B35: 0 | C35: عملاء كاش | D35: الدفع الفوري | E35: AbdElrhaman Farrag | F35: 0 | G35: 514976 | H35: -34.2 | I35: 0 | J35: 0 | K35: 0 | L35: 514941.8
A36: السويفى ( عميل ومورد ) | B36: MAS | C36: عميل - مورد | D36: الدفع الفوري | E36: Haddil Haron | F36: 0 | G36: 5667.89 | H36: 487719 | I36: 0 | J36: 0 | K36: 0 | L36: 493386.89
A37: بهيج | B37: MAS | C37: عملاء اجل | D37: 30 يوماً | E37: Haddil Haron | F37: 0 | G37: 0 | H37: 0 | I37: 0 | J37: 408176.14 | K37: 0 | L37: 408176.14
A38: Horeca Hub | B38: Horeca Smart | C38: عملاء اجل | D38: 15 يوماً | E38: Mona Mohamed | F38: 779581.01 | G38: -383008.8 | H38: 0 | I38: 0 | J38: 644.67 | K38: 0 | L38: 397216.88
A39: شركة عزايم للصناعات الغذائية (ديوكس) | B39: MAS | C39: عملاء اجل | D39: 15 of month | E39: Haddil Haron | F39: 252514.18 | G39: 0 | H39: 22032.9 | I39: 107008.7 | J39: 1.1 | K39: 0 | L39: 381556.88
A40: ريفولى | B40: MAS | C40: عملاء اجل | D40: 30 يوماً | E40: Haddil Haron | F40: 192848.5 | G40: 12607 | H40: 62442.7 | I40: 0 | J40: 96706.42 | K40: 0 | L40: 364604.62
A41: احمد يوسف ( عميل و مورد ) | B41: MAS | C41: عميل - مورد | D41: 5 Days | E41: Haddil Haron | F41: 0 | G41: 0 | H41: 0 | I41: 0 | J41: 363946.82 | K41: 0 | L41: 363946.82
...

Sheet 16-09
A1: المتأخر المدين حتى 16-09-2026
A3: المتأخر المدين | B3: الشركة | C3: علامات التصنيف | D3: شروط السداد للعميل | E3: مندوب المبيعات | F3: بتاريخ | G3: 1-30 | H3: 31-60 | I3: 61-90 | J3: 91-120 | K3: أقدم | L3: الإجمالي
F4: =SUBTOTAL(9,F5:F233) -> 14287612 | G4: =SUBTOTAL(9,G5:G233) -> 22058708 | H4: =SUBTOTAL(9,H5:H233) -> 12011433 | I4: =SUBTOTAL(9,I5:I233) -> 1623862.8 | J4: =SUBTOTAL(9,J5:J233) -> 11454552 | K4: =SUBTOTAL(9,K5:K233) -> 0 | L4: =F4+G4+H4+I4+J4 -> 61436168
A5: خالد حسين (عميل - مورد) | B5: =VLOOKUP(A5,'[1]تحديث العملاء'!$A:$D,2,0) -> 0 | C5: =VLOOKUP(A5,'[1]تحديث العملاء'!$A:$D,3,0) -> عميل - مورد | D5: =VLOOKUP(A5,'09-09'!A:L,4,0) -> 0 | E5: =VLOOKUP(A5,'[1]تحديث العملاء'!$A:$D,4,0) -> Haddil Haron | F5: 0 | G5: 1213450 | H5: 7014154.9 | I5: 37926.29 | J5: 596748.59 | L5: =F5+G5+H5+I5+J5 -> 8862279.8
A6: تسيباس اوول فوود | B6: =VLOOKUP(A6,'[1]تحديث العملاء'!$A:$D,2,0) -> MAS | C6: =VLOOKUP(A6,'[1]تحديث العملاء'!$A:$D,3,0) -> عملاء اجل | D6: =VLOOKUP(A6,'09-09'!A:L,4,0) -> 30 يوماً | E6: =VLOOKUP(A6,'[1]تحديث العملاء'!$A:$D,4,0) -> Haddil Haron | F6: 1141227.5 | G6: 2691012.5 | H6: 35846 | I6: 214841.5 | J6: 190187.66 | L6: =F6+G6+H6+I6+J6 -> 4273115.1
A7: فوالا | B7: =VLOOKUP(A7,'[1]تحديث العملاء'!$A:$D,2,0) -> MAS | C7: =VLOOKUP(A7,'[1]تحديث العملاء'!$A:$D,3,0) -> عملاء اجل | D7: =VLOOKUP(A7,'09-09'!A:L,4,0) -> 60 يوم | E7: =VLOOKUP(A7,'[1]تحديث العملاء'!$A:$D,4,0) -> Haddil Haron | F7: 1655148.2 | G7: 110499.2 | H7: 486645.6 | I7: 16368 | J7: 582364.27 | L7: =F7+G7+H7+I7+J7 -> 2851025.3
A8: ايتوال | B8: =VLOOKUP(A8,'[1]تحديث العملاء'!$A:$D,2,0) -> MAS | C8: =VLOOKUP(A8,'[1]تحديث العملاء'!$A:$D,3,0) -> عملاء اجل | D8: =VLOOKUP(A8,'09-09'!A:L,4,0) -> 15 of month | E8: =VLOOKUP(A8,'[1]تحديث العملاء'!$A:$D,4,0) -> Haddil Haron | F8: 858085.5 | G8: 1824701.2 | H8: 0 | I8: 0 | J8: 0 | L8: =F8+G8+H8+I8+J8 -> 2682786.7
A9: سدرة - للحلويات | B9: =VLOOKUP(A9,'[1]تحديث العملاء'!$A:$D,2,0) -> MAS | C9: =VLOOKUP(A9,'[1]تحديث العملاء'!$A:$D,3,0) -> عملاء اجل | D9: =VLOOKUP(A9,'09-09'!A:L,4,0) -> 15 of month | E9: =VLOOKUP(A9,'[1]تحديث العملاء'!$A:$D,4,0) -> Haddil Haron | F9: 94852.76 | G9: 712013.79 | H9: 793521.9 | I9: 0 | J9: 927344.29 | L9: =F9+G9+H9+I9+J9 -> 2527732.7
A10: مصنع بريد فاست | B10: =VLOOKUP(A10,'[1]تحديث العملاء'!$A:$D,2,0) -> MAS | C10: =VLOOKUP(A10,'[1]تحديث العملاء'!$A:$D,3,0) -> عملاء اجل | D10: =VLOOKUP(A10,'09-09'!A:L,4,0) -> 30 يوماً | E10: =VLOOKUP(A10,'[1]تحديث العملاء'!$A:$D,4,0) -> Haddil Haron | F10: 422280 | G10: 1759611 | H10: 0 | I10: 0 | J10: 46254.23 | L10: =F10+G10+H10+I10+J10 -> 2228145.2
A11: زانوبيا | B11: =VLOOKUP(A11,'[1]تحديث العملاء'!$A:$D,2,0) -> MAS | C11: =VLOOKUP(A11,'[1]تحديث العملاء'!$A:$D,3,0) -> عملاء اجل | D11: =VLOOKUP(A11,'09-09'!A:L,4,0) -> 15 of month | E11: =VLOOKUP(A11,'[1]تحديث العملاء'!$A:$D,4,0) -> Haddil Haron | F11: 472785 | G11: 1225775 | H11: 129921.94 | I11: 210000 | J11: 0 | L11: =F11+G11+H11+I11+J11 -> 2038481.9
A12: Abela | B12: =VLOOKUP(A12,'[1]تحديث العملاء'!$A:$D,2,0) -> MAS | C12: =VLOOKUP(A12,'[1]تحديث العملاء'!$A:$D,3,0) -> عملاء اجل | D12: =VLOOKUP(A12,'09-09'!A:L,4,0) -> 30 يوماً | E12: =VLOOKUP(A12,'[1]تحديث العملاء'!$A:$D,4,0) -> Haddil Haron | F12: 1715648.5 | G12: 214699.27 | H12: 0 | I12: 0 | J12: 0 | L12: =F12+G12+H12+I12+J12 -> 1930347.8
A13: نولا | B13: =VLOOKUP(A13,'[1]تحديث العملاء'!$A:$D,2,0) -> MAS | C13: =VLOOKUP(A13,'[1]تحديث العملاء'!$A:$D,3,0) -> عملاء اجل | D13: =VLOOKUP(A13,'09-09'!A:L,4,0) -> 15 of month | E13: =VLOOKUP(A13,'[1]تحديث العملاء'!$A:$D,4,0) -> Haddil Haron | F13: 411936 | G13: 1293044 | H13: 148161.48 | I13: 0 | J13: 0 | L13: =F13+G13+H13+I13+J13 -> 1853141.5
A14: مطعم مايند دن | B14: =VLOOKUP(A14,'[1]تحديث العملاء'!$A:$D,2,0) -> MAS | C14: =VLOOKUP(A14,'[1]تحديث العملاء'!$A:$D,3,0) -> عملاء اجل | D14: =VLOOKUP(A14,'09-09'!A:L,4,0) -> 30 يوماً | E14: =VLOOKUP(A14,'[1]تحديث العملاء'!$A:$D,4,0) -> Haddil Haron | F14: 892905.56 | G14: 625911.44 | H14: 60970.1 | I14: 0 | J14: 22.1 | L14: =F14+G14+H14+I14+J14 -> 1579809.2
A15: توينكى | B15: =VLOOKUP(A15,'[1]تحديث العملاء'!$A:$D,2,0) -> MAS | C15: =VLOOKUP(A15,'[1]تحديث العملاء'!$A:$D,3,0) -> متجمد | D15: =VLOOKUP(A15,'09-09'!A:L,4,0) -> 0 | E15: =VLOOKUP(A15,'[1]تحديث العملاء'!$A:$D,4,0) -> Naden Amgad | F15: 0 | G15: 0 | H15: 0 | I15: 0 | J15: 1478937 | L15: =F15+G15+H15+I15+J15 -> 1478937
A16: ماتانا للمنتجات الغذائية | B16: =VLOOKUP(A16,'[1]تحديث العملاء'!$A:$D,2,0) -> MAS | C16: =VLOOKUP(A16,'[1]تحديث العملاء'!$A:$D,3,0) -> عملاء اجل | D16: =VLOOKUP(A16,'09-09'!A:L,4,0) -> 30 يوماً | E16: =VLOOKUP(A16,'[1]تحديث العملاء'!$A:$D,4,0) -> Haddil Haron | F16: 738658.75 | G16: 683306.51 | H16: 0 | I16: 0 | J16: 0 | L16: =F16+G16+H16+I16+J16 -> 1421965.3
... A233: Bja company | B233: =VLOOKUP(A233,'[1]تحديث العملاء'!$A:$D,2,0) -> Horeca Smart | C233: =VLOOKUP(A233,'[1]تحديث العملاء'!$A:$D,3,0) -> عملاء كاش | D233: =VLOOKUP(A233,'09-09'!A:L,4,0) -> الدفع الفوري | E233: =VLOOKUP(A233,'[1]تحديث العملاء'!$A:$D,4,0) -> Reham Maher | F233: 0 | G233: 0 | H233: 246 | I233: 0 | J233: -55.48 | L233: =F233+G233+H233+I233+J233 -> 190.52
A234: مستر بيتزا | F234: 0 | G234: 180.5 | H234: 0 | I234: 0 | J234: 0
A235: The Best Supplies | F235: 0 | G235: 0 | H235: 0 | I235: 0 | J235: 80
A236: Motor sprots HUB | F236: 0 | G236: 0 | H236: 50 | I236: 0 | J236: 0
A237: ألميرا | F237: 0 | G237: 0 | H237: 19.98 | I237: 0 | J237: 0
A238: الهادي نيو لتوريد المواد الغذائية | F238: 0 | G238: 0 | H238: 5 | I238: 0 | J238: 0
A239: 3BOYS Supplies Company | F239: 0 | G239: 0 | H239: 2.52 | I239: 0 | J239: 0
A240: Simonds Bakery | F240: 0 | G240: 2.1 | H240: 0 | I240: 0 | J240: 0
A241: Rivo Cafe - العبور | F241: 0 | G241: 4.5 | H241: -2.75 | I241: 0 | J241: 0
A242: Big Boy Restaurant | F242: 0 | G242: 0 | H242: 1.25 | I242: 0 | J242: 0
A243: Mountain cafe | F243: 0 | G243: 0 | H243: 1 | I243: 0 | J243: 0
A244: BRB Coffee | F244: 0 | G244: 0 | H244: 1 | I244: 0 | J244: 0
A245: نووك نووك تشويز | F245: 0 | G245: -1.08 | H245: 1.04 | I245: 0.75 | J245: 0
... A441: Horeca Hub | F441: 609189.67 | G441: -747568.8 | H441: -250630.49 | I441: 31474.17 | J441: 644.67
